<?xml version="1.0" ?>
<robot name="kuka">
  <display brand="KUKA" pc_as_master_control="true" robot_as_master_control="true" external_control="false" model="KR 50 R2500-E" axes="6" reach="2500 mm" payload="50 kg" weight="530 kg" repeatability="0.050 mm">
  </display>
  <initial joints="0.0 -1.5707963267948966 1.5707963267948966 0.0 0.0 0.0">
  </initial>
  <transform tf_rb_ub="0.0 0.0 0.0 0.0 0.0 0.0 1.0" tf_rf_uf="0.0 0.0 0.0 0.0 0.0 0.0 1.0">
  </transform>
  <constraint coeff="0.0 0.0 0.0 1.0 0.0 0.0" lower_bound="0.0" upper_bound="0.0"/>
  <constraint coeff="0.0 1.0 1.0 0.0 1.0 0.0" lower_bound="1.5707963267948966" upper_bound="1.5707963267948966"/>
  <!-- <link name="world" /> -->
  
  <link name="base_link">
    <visual>
      <origin rpy="0 0 0" xyz="0 0 0"/>
      <geometry>
        <mesh filename="package://kuka_description/meshes/visual/base_link.stl"/>
      </geometry>
      <material name="">
        <color rgba="0.054901960784313725 0.054901960784313725 0.06274509803921569 1.0"/>
      </material>
    </visual>
    <collision>
      <origin rpy="0 0 0" xyz="0 0 0"/>
      <geometry>
        <mesh filename="package://kuka_description/meshes/collision/base_link.stl"/>
      </geometry>
    </collision>
  </link>
  <link name="link_1">
    <visual>
      <origin rpy="0 0 0" xyz="0 0 -0.557"/>
      <geometry>
        <mesh filename="package://kuka_description/meshes/visual/link_1.stl"/>
      </geometry>
      <material name="">
        <color rgba="0.9647058823529412 0.47058823529411764 0.1568627450980392 1.0"/>
      </material>
    </visual>
    <collision>
      <origin rpy="0 0 0" xyz="0 0 -0.557"/>
      <geometry>
        <mesh filename="package://kuka_description/meshes/collision/link_1.stl"/>
      </geometry>
    </collision>
  </link>
  <link name="link_2">
    <visual>
      <origin rpy="0 0 0" xyz="-0.190 0 -0.557"/>
      <geometry>
        <mesh filename="package://kuka_description/meshes/visual/link_2.stl"/>
      </geometry>
      <material name="">
        <color rgba="0.9647058823529412 0.47058823529411764 0.1568627450980392 1.0"/>
      </material>
    </visual>
    <collision>
      <origin rpy="0 0 0" xyz="-0.190 0 -0.557"/>
      <geometry>
        <mesh filename="package://kuka_description/meshes/collision/link_2.stl"/>
      </geometry>
    </collision>
  </link>
  <link name="link_3">
    <visual>
      <origin rpy="0 0 0" xyz="-0.190 0 -1.647"/>
      <geometry>
        <mesh filename="package://kuka_description/meshes/visual/link_3.stl"/>
      </geometry>
      <material name="">
        <color rgba="0.9647058823529412 0.47058823529411764 0.1568627450980392 1.0"/>
      </material>
    </visual>
    <collision>
      <origin rpy="0 0 0" xyz="-0.190 0 -1.647"/>
      <geometry>
        <mesh filename="package://kuka_description/meshes/collision/link_3.stl"/>
      </geometry>
    </collision>
  </link>
  <link name="link_4">
    <visual>
      <origin rpy="0 0 0" xyz="-0.190 0 -1.797"/>
      <geometry>
        <mesh filename="package://kuka_description/meshes/visual/link_4.stl"/>
      </geometry>
      <material name="">
        <color rgba="0.9647058823529412 0.47058823529411764 0.1568627450980392 1.0"/>
      </material>
    </visual>
    <collision>
      <origin rpy="0 0 0" xyz="-0.190 0 -1.797"/>
      <geometry>
        <mesh filename="package://kuka_description/meshes/collision/link_4.stl"/>
      </geometry>
    </collision>
  </link>
  <link name="link_5">
    <visual>
      <origin rpy="0 0 0" xyz="-1.401 0 -1.797"/>
      <geometry>
        <mesh filename="package://kuka_description/meshes/visual/link_5.stl"/>
      </geometry>
      <material name="">
        <color rgba="0.9647058823529412 0.47058823529411764 0.1568627450980392 1.0"/>
      </material>
    </visual>
    <collision>
      <origin rpy="0 0 0" xyz="-1.401 0 -1.797"/>
      <geometry>
        <mesh filename="package://kuka_description/meshes/collision/link_5.stl"/>
      </geometry>
    </collision>
  </link>
  <link name="link_6">
    <visual>
      <origin rpy="0 0 0" xyz="0 0 0"/>
      <geometry>
        <mesh filename="package://kuka_description/meshes/visual/link_6.stl"/>
      </geometry>
      <material name="">
        <color rgba="0.5058823529411764 0.47058823529411764 0.38823529411764707 1.0"/>
      </material>
    </visual>
    <collision>
      <origin rpy="0 0 0" xyz="0 0 0"/>
      <geometry>
        <mesh filename="package://kuka_description/meshes/collision/link_6.stl"/>
      </geometry>
    </collision>
  </link>
  <!-- This frame corresponds to the $FLANGE coordinate system in KUKA KRC controllers. -->
  <!-- <joint name="world_to_base" type="fixed">
    <origin xyz="0 0 0" rpy="0 0 0.78539816338" />
    <parent link="world" />
    <child link="base_link" />
  </joint> -->
  <joint name="joint1" type="revolute">
    <origin rpy="0 0 0" xyz="0 0 0.557"/>
    <parent link="base_link"/>
    <child link="link_1"/>
    <axis xyz="0 0 -1"/>
    <limit effort="0" lower="-3.2288591161895095" upper="3.2288591161895095" velocity="3.0543261909900767"/>
  </joint>
  <joint name="joint2" type="revolute">
    <origin rpy="0 1.5707963267948966 0" xyz="0.190 0 0"/>
    <parent link="link_1"/>
    <child link="link_2"/>
    <axis xyz="0 1 0"/>
    <limit effort="0" lower="-3.0543261909900767" upper="1.0471975511965976" velocity="2.7576202181510405"/>
  </joint>
  <joint name="joint3" type="revolute">
    <origin rpy="0 -1.5707963267948966 0" xyz="0 0 1.090"/>
    <parent link="link_2"/>
    <child link="link_3"/>
    <axis xyz="0 1 0"/>
    <limit effort="0" lower="-2.0943951023931953" upper="2.8797932657906435" velocity="3.0543261909900767"/>
  </joint>
  <joint name="joint4" type="revolute">
    <origin rpy="0 0 0" xyz="0 0 0.150"/>
    <parent link="link_3"/>
    <child link="link_4"/>
    <axis xyz="-1 0 0"/>
    <limit effort="0" lower="-3.141592653589793" upper="3.141592653589793" velocity="4.363323129985824"/>
  </joint>
  <joint name="joint5" type="revolute">
    <origin rpy="0 0 0" xyz="1.211 0 0"/>
    <parent link="link_4"/>
    <child link="link_5"/>
    <axis xyz="0 1 0"/>
    <limit effort="0" lower="-2.181661564992912" upper="2.181661564992912" velocity="4.363323129985824"/>
  </joint>
  <joint name="joint6" type="revolute">
    <origin rpy="0 1.5707963267948966 0" xyz="0.1849 0 0"/>
    <parent link="link_5"/>
    <child link="link_6"/>
    <axis xyz="0 0 -1"/>
    <limit effort="0" lower="-3.1416" upper="3.1416" velocity="6.283185307179586"/>
  </joint>
</robot>
