<?xml version="1.0" ?>
<!-- =================================================================================== -->
<!-- |    This document was autogenerated by xacro from src/kuka_description/urdf/assembly_moveit.xacro | -->
<!-- |    EDITING THIS FILE BY HAND IS NOT RECOMMENDED                                 | -->
<!-- =================================================================================== -->
<robot name="assembly_moveit">
  <display axes="6" brand="KUKA" external_control="false" model="KR 50 R2500-E" payload="50 kg" pc_as_master_control="true" reach="2500 mm" repeatability="0.050 mm" robot_as_master_control="true" weight="530 kg">
  </display>
  <initial joints="0.0 -1.5707963267948966 1.5707963267948966 0.0 0.0 0.0">
  </initial>
  <transform tf_rb_ub="0.0 0.0 0.0 0.0 0.0 0.0 1.0" tf_rf_uf="0.0 0.0 0.0 0.0 0.0 0.0 1.0">
  </transform>
  <constraint coeff="0.0 0.0 0.0 1.0 0.0 0.0" lower_bound="0.0" upper_bound="0.0"/>
  <constraint coeff="0.0 1.0 1.0 0.0 1.0 0.0" lower_bound="1.5707963267948966" upper_bound="1.5707963267948966"/>
  <!-- <link name="world" /> -->
  <link name="base_link">
    <visual>
      <origin rpy="0 0 0" xyz="0 0 0"/>
      <geometry>
        <mesh filename="package://kuka_description/meshes/visual/base_link.stl"/>
      </geometry>
      <material name="">
        <color rgba="0.054901960784313725 0.054901960784313725 0.06274509803921569 1.0"/>
      </material>
    </visual>
    <collision>
      <origin rpy="0 0 0" xyz="0 0 0"/>
      <geometry>
        <mesh filename="package://kuka_description/meshes/collision/base_link.stl"/>
      </geometry>
    </collision>
  </link>
  <link name="link_1">
    <visual>
      <origin rpy="0 0 0" xyz="0 0 -0.557"/>
      <geometry>
        <mesh filename="package://kuka_description/meshes/visual/link_1.stl"/>
      </geometry>
      <material name="">
        <color rgba="0.9647058823529412 0.47058823529411764 0.1568627450980392 1.0"/>
      </material>
    </visual>
    <collision>
      <origin rpy="0 0 0" xyz="0 0 -0.557"/>
      <geometry>
        <mesh filename="package://kuka_description/meshes/collision/link_1.stl"/>
      </geometry>
    </collision>
  </link>
  <link name="link_2">
    <visual>
      <origin rpy="0 0 0" xyz="-0.190 0 -0.557"/>
      <geometry>
        <mesh filename="package://kuka_description/meshes/visual/link_2.stl"/>
      </geometry>
      <material name="">
        <color rgba="0.9647058823529412 0.47058823529411764 0.1568627450980392 1.0"/>
      </material>
    </visual>
    <collision>
      <origin rpy="0 0 0" xyz="-0.190 0 -0.557"/>
      <geometry>
        <mesh filename="package://kuka_description/meshes/collision/link_2.stl"/>
      </geometry>
    </collision>
  </link>
  <link name="link_3">
    <visual>
      <origin rpy="0 0 0" xyz="-0.190 0 -1.647"/>
      <geometry>
        <mesh filename="package://kuka_description/meshes/visual/link_3.stl"/>
      </geometry>
      <material name="">
        <color rgba="0.9647058823529412 0.47058823529411764 0.1568627450980392 1.0"/>
      </material>
    </visual>
    <collision>
      <origin rpy="0 0 0" xyz="-0.190 0 -1.647"/>
      <geometry>
        <mesh filename="package://kuka_description/meshes/collision/link_3.stl"/>
      </geometry>
    </collision>
  </link>
  <link name="link_4">
    <visual>
      <origin rpy="0 0 0" xyz="-0.190 0 -1.797"/>
      <geometry>
        <mesh filename="package://kuka_description/meshes/visual/link_4.stl"/>
      </geometry>
      <material name="">
        <color rgba="0.9647058823529412 0.47058823529411764 0.1568627450980392 1.0"/>
      </material>
    </visual>
    <collision>
      <origin rpy="0 0 0" xyz="-0.190 0 -1.797"/>
      <geometry>
        <mesh filename="package://kuka_description/meshes/collision/link_4.stl"/>
      </geometry>
    </collision>
  </link>
  <link name="link_5">
    <visual>
      <origin rpy="0 0 0" xyz="-1.401 0 -1.797"/>
      <geometry>
        <mesh filename="package://kuka_description/meshes/visual/link_5.stl"/>
      </geometry>
      <material name="">
        <color rgba="0.9647058823529412 0.47058823529411764 0.1568627450980392 1.0"/>
      </material>
    </visual>
    <collision>
      <origin rpy="0 0 0" xyz="-1.401 0 -1.797"/>
      <geometry>
        <mesh filename="package://kuka_description/meshes/collision/link_5.stl"/>
      </geometry>
    </collision>
  </link>
  <link name="link_6">
    <visual>
      <origin rpy="0 0 0" xyz="0 0 0"/>
      <geometry>
        <mesh filename="package://kuka_description/meshes/visual/link_6.stl"/>
      </geometry>
      <material name="">
        <color rgba="0.5058823529411764 0.47058823529411764 0.38823529411764707 1.0"/>
      </material>
    </visual>
    <collision>
      <origin rpy="0 0 0" xyz="0 0 0"/>
      <geometry>
        <mesh filename="package://kuka_description/meshes/collision/link_6.stl"/>
      </geometry>
    </collision>
  </link>
  <!-- This frame corresponds to the $FLANGE coordinate system in KUKA KRC controllers. -->
  <!-- <joint name="world_to_base" type="fixed">
    <origin xyz="0 0 0" rpy="0 0 0.78539816338" />
    <parent link="world" />
    <child link="base_link" />
  </joint> -->
  <joint name="joint1" type="revolute">
    <origin rpy="0 0 0" xyz="0 0 0.557"/>
    <parent link="base_link"/>
    <child link="link_1"/>
    <axis xyz="0 0 -1"/>
    <limit effort="0" lower="-3.2288591161895095" upper="3.2288591161895095" velocity="3.0543261909900767"/>
  </joint>
  <joint name="joint2" type="revolute">
    <origin rpy="0 1.5707963267948966 0" xyz="0.190 0 0"/>
    <parent link="link_1"/>
    <child link="link_2"/>
    <axis xyz="0 1 0"/>
    <limit effort="0" lower="-3.0543261909900767" upper="1.0471975511965976" velocity="2.7576202181510405"/>
  </joint>
  <joint name="joint3" type="revolute">
    <origin rpy="0 -1.5707963267948966 0" xyz="0 0 1.090"/>
    <parent link="link_2"/>
    <child link="link_3"/>
    <axis xyz="0 1 0"/>
    <limit effort="0" lower="-2.0943951023931953" upper="2.8797932657906435" velocity="3.0543261909900767"/>
  </joint>
  <joint name="joint4" type="revolute">
    <origin rpy="0 0 0" xyz="0 0 0.150"/>
    <parent link="link_3"/>
    <child link="link_4"/>
    <axis xyz="-1 0 0"/>
    <limit effort="0" lower="-3.141592653589793" upper="3.141592653589793" velocity="4.363323129985824"/>
  </joint>
  <joint name="joint5" type="revolute">
    <origin rpy="0 0 0" xyz="1.211 0 0"/>
    <parent link="link_4"/>
    <child link="link_5"/>
    <axis xyz="0 1 0"/>
    <limit effort="0" lower="-2.181661564992912" upper="2.181661564992912" velocity="4.363323129985824"/>
  </joint>
  <joint name="joint6" type="revolute">
    <origin rpy="0 1.5707963267948966 0" xyz="0.1849 0 0"/>
    <parent link="link_5"/>
    <child link="link_6"/>
    <axis xyz="0 0 -1"/>
    <limit effort="0" lower="-6.1086523819801535" upper="6.1086523819801535" velocity="6.283185307179586"/>
  </joint>
  <!-- <link name="world" >
    <inertial>
      <origin xyz="0 0 0" rpy="0 0 0" />
    </inertial>
  </link> -->
  <!-- <joint name="world_to_base" type="fixed">
    <origin xyz="0 0 0" rpy="-1.5707963267949 0 3.1415926535" />
    <parent link="world" />
    <child link="env_base_link" />
  </joint> -->
  <link name="env_base_link">
    <inertial>
      <origin rpy="0 0 0" xyz="2.04292309020355E-05 -2.48495608706582E-05 -0.74765039105253"/>
      <mass value="27.4260952170301"/>
      <inertia ixx="1.055670395445" ixy="3.04369272653359E-07" ixz="4.60037879678673E-07" iyy="1.05567006631963" iyz="-2.04091859392645E-07" izz="0.229049982407926"/>
    </inertial>
    <visual>
      <origin rpy="0 0 0" xyz="0 0 0"/>
      <geometry>
        <mesh filename="package://env_description/meshes/env_base_link.STL"/>
      </geometry>
      <material name="">
        <color rgba="0.529411764705882 0.549019607843137 0.549019607843137 1"/>
      </material>
    </visual>
    <collision>
      <origin rpy="0 0 0" xyz="0 0 0"/>
      <geometry>
        <mesh filename="package://env_description/meshes/env_base_link.STL"/>
      </geometry>
    </collision>
  </link>
  <link name="zone1">
    <inertial>
      <origin rpy="0 0 0" xyz="0.000237522347327546 0.0861311047423845 0.000100011865945548"/>
      <mass value="100.806877066515"/>
      <inertia ixx="9.03367081219723" ixy="6.03464433334203E-11" ixz="-4.49064746216151E-05" iyy="20.8048542387601" iyz="-1.21612325080903E-05" izz="12.439411115673"/>
    </inertial>
    <visual>
      <origin rpy="0 0 0" xyz="0 0 0"/>
      <geometry>
        <mesh filename="package://env_description/meshes/zone1.STL"/>
      </geometry>
      <material name="">
        <color rgba="0.196078431372549 0.666666666666667 1 1"/>
      </material>
    </visual>
    <collision>
      <origin rpy="0 0 0" xyz="0 0 0"/>
      <geometry>
        <mesh filename="package://env_description/meshes/zone1.STL"/>
      </geometry>
    </collision>
  </link>
  <joint name="joint_zone1" type="fixed">
    <origin rpy="0 1.5707963267949 0" xyz="-1.45 0.793000000000044 0.800000000002483"/>
    <parent link="env_base_link"/>
    <child link="zone1"/>
    <axis xyz="0 0 0"/>
  </joint>
  <link name="zone2">
    <inertial>
      <origin rpy="0 0 0" xyz="-0.000237522346957397 0.0861311047423874 -0.000100011865940219"/>
      <mass value="100.806877066515"/>
      <inertia ixx="9.03367081219723" ixy="-6.03218668176874E-11" ixz="-4.49064746210582E-05" iyy="20.8048542387601" iyz="1.21612325480791E-05" izz="12.439411115673"/>
    </inertial>
    <visual>
      <origin rpy="0 0 0" xyz="0 0 0"/>
      <geometry>
        <mesh filename="package://env_description/meshes/zone2.STL"/>
      </geometry>
      <material name="">
        <color rgba="0.196078431372549 0.666666666666667 1 1"/>
      </material>
    </visual>
    <collision>
      <origin rpy="0 0 0" xyz="0 0 0"/>
      <geometry>
        <mesh filename="package://env_description/meshes/zone2.STL"/>
      </geometry>
    </collision>
  </link>
  <joint name="joint_zone2" type="fixed">
    <origin rpy="0 -1.5707963267949 0" xyz="-1.45 0.793000000000005 -0.800000000002485"/>
    <parent link="env_base_link"/>
    <child link="zone2"/>
    <axis xyz="0 0 0"/>
  </joint>
  <link name="zone3">
    <inertial>
      <origin rpy="0 0 0" xyz="-0.0684415439431976 -0.218698244858344 1.44070096264048E-05"/>
      <mass value="699.790180593656"/>
      <inertia ixx="25.9701557382707" ixy="6.0348614956271E-11" ixz="-4.49064746236056E-05" iyy="41.2289346553203" iyz="-1.21612325085197E-05" izz="24.8899887523743"/>
    </inertial>
    <visual>
      <origin rpy="0 0 0" xyz="0 0 0"/>
      <geometry>
        <mesh filename="package://env_description/meshes/zone3.STL"/>
      </geometry>
      <material name="">
        <color rgba="0.196078431372549 0.666666666666667 1 1"/>
      </material>
    </visual>
    <collision>
      <origin rpy="0 0 0" xyz="0 0 0"/>
      <geometry>
        <mesh filename="package://env_description/meshes/zone3.STL"/>
      </geometry>
    </collision>
  </link>
  <joint name="joint_zone3" type="fixed">
    <origin rpy="0 1.5707963267949 0" xyz="-1.44999999999999 0.793 2.3999999999995"/>
    <parent link="env_base_link"/>
    <child link="zone3"/>
    <axis xyz="0 0 0"/>
  </joint>
  <link name="zone4">
    <inertial>
      <origin rpy="3.1415926535 0 0" xyz="-0.0617980925454238 -0.21379899491032 -0.0252814866128777"/>
      <mass value="638.786876463627"/>
      <inertia ixx="17.0676082368567" ixy="-6.0321327128845E-11" ixz="-4.49064746227642E-05" iyy="26.6057193451958" iyz="1.21612325479998E-05" izz="18.2402762221087"/>
    </inertial>
    <visual>
      <origin rpy="0 0 0" xyz="0 0 0"/>
      <geometry>
        <mesh filename="package://env_description/meshes/zone4.STL"/>
      </geometry>
      <material name="">
        <color rgba="0.196078431372549 0.666666666666667 1 1"/>
      </material>
    </visual>
    <collision>
      <origin rpy="0 0 0" xyz="0 0 0"/>
      <geometry>
        <mesh filename="package://env_description/meshes/zone4.STL"/>
      </geometry>
    </collision>
  </link>
  <joint name="joint_zone4" type="fixed">
    <origin rpy="0 1.5707963267949 0" xyz="-1.44999999999995 0.793 -2.39999999999951"/>
    <parent link="env_base_link"/>
    <child link="zone4"/>
    <axis xyz="0 0 0"/>
  </joint>
  <link name="zoneA">
    <inertial>
      <origin rpy="0 0 0" xyz="-0.00556468281280154 0.0894724701778807 -0.00561599115213774"/>
      <mass value="99.715164345799"/>
      <inertia ixx="8.77395649875361" ixy="1.36344939772128E-05" ixz="1.08961255720256E-05" iyy="20.1394886687233" iyz="-5.44444304885452E-06" izz="12.0962092500586"/>
    </inertial>
    <visual>
      <origin rpy="0 0 0" xyz="0 0 0"/>
      <geometry>
        <mesh filename="package://env_description/meshes/zoneA.STL"/>
      </geometry>
      <material name="">
        <color rgba="0.196078431372549 0.666666666666667 1 1"/>
      </material>
    </visual>
    <collision>
      <origin rpy="0 0 0" xyz="0 0 0"/>
      <geometry>
        <mesh filename="package://env_description/meshes/zoneA.STL"/>
      </geometry>
    </collision>
  </link>
  <joint name="joint_zoneA" type="fixed">
    <origin rpy="0 1.5707963267949 0" xyz="0 0.735000000000003 1.7"/>
    <parent link="env_base_link"/>
    <child link="zoneA"/>
    <axis xyz="0 0 0"/>
  </joint>
  <link name="zoneB">
    <inertial>
      <origin rpy="0 0 0" xyz="-0.00564147016359562 0.0894613477658045 -0.0056520834470133"/>
      <mass value="99.7231029444658"/>
      <inertia ixx="8.77395734615948" ixy="1.36214125589424E-05" ixz="1.08961707386281E-05" iyy="20.1394890220497" iyz="-5.44440895801658E-06" izz="12.0962102730413"/>
    </inertial>
    <visual>
      <origin rpy="0 0 0" xyz="0 0 0"/>
      <geometry>
        <mesh filename="package://env_description/meshes/zoneB.STL"/>
      </geometry>
      <material name="">
        <color rgba="0.196078431372549 0.666666666666667 1 1"/>
      </material>
    </visual>
    <collision>
      <origin rpy="0 0 0" xyz="0 0 0"/>
      <geometry>
        <mesh filename="package://env_description/meshes/zoneB.STL"/>
      </geometry>
    </collision>
  </link>
  <joint name="joint_zoneB" type="fixed">
    <origin rpy="0 1.5707963267949 0" xyz="0 0.734999999999994 -1.7"/>
    <parent link="env_base_link"/>
    <child link="zoneB"/>
    <axis xyz="0 0 0"/>
  </joint>
  <link name="guardrail">
    <inertial>
      <origin rpy="0 0 0" xyz="1.52945296499415 2.77839337918363 1.18128363457791"/>
      <mass value="66.2326402785299"/>
      <inertia ixx="20.202768353338" ixy="9.58691029424039E-06" ixz="1.92701052171936E-07" iyy="18.6513859456777" iyz="0.00114703806405233" izz="3.05066480704414"/>
    </inertial>
    <visual>
      <origin rpy="0 0 0" xyz="0 0 0"/>
      <geometry>
        <mesh filename="package://env_description/meshes/guardrail.STL"/>
      </geometry>
      <material name="">
        <color rgba="1 1 0 1"/>
      </material>
    </visual>
    <collision>
      <origin rpy="0 0 0" xyz="0 0 0"/>
      <geometry>
        <mesh filename="package://env_description/meshes/guardrail.STL"/>
      </geometry>
    </collision>
  </link>
  <joint name="joint_guardrail" type="fixed">
    <origin rpy="1.5707963267949 1.5707963267949 0" xyz="-3.20000000000002 1.21499999998898 1.59999999999988"/>
    <parent link="env_base_link"/>
    <child link="guardrail"/>
    <axis xyz="0 0 0"/>
  </joint>
  <link name="vision_system">
    <inertial>
      <origin rpy="0 0 0" xyz="-0.034883316910409 0.000102981255213192 -0.976502657407548"/>
      <mass value="78.2001040178106"/>
      <inertia ixx="102.210333883345" ixy="4.10912018646278E-06" ixz="-5.2151993759076E-05" iyy="42.0443800501756" iyz="0.000122747659944404" izz="67.4194518411167"/>
    </inertial>
    <visual>
      <origin rpy="0 0 0" xyz="0 0 0"/>
      <geometry>
        <mesh filename="package://env_description/meshes/vision_system.STL"/>
      </geometry>
      <material name="">
        <color rgba="0.898039215686275 0.917647058823529 0.929411764705882 1"/>
      </material>
    </visual>
    <collision>
      <origin rpy="0 0 0" xyz="0 0 0"/>
      <geometry>
        <mesh filename="package://env_description/meshes/vision_system.STL"/>
      </geometry>
    </collision>
  </link>
  <joint name="joint_vision_system" type="fixed">
    <origin rpy="1.5707963267949 0 0" xyz="0 -2.8249999997787 0"/>
    <parent link="env_base_link"/>
    <child link="vision_system"/>
    <axis xyz="0 0 0"/>
  </joint>
  <link name="tray">
    <inertial>
      <origin rpy="0 0 0" xyz="-2.22044604925031E-16 0.76001495141375 -8.26827729881031E-15"/>
      <mass value="938.309751487932"/>
      <inertia ixx="84.7356654369977" ixy="8.97107870569259E-14" ixz="-2.71788029260789E-13" iyy="198.670510817625" iyz="8.41121573525212E-14" izz="120.63337253658"/>
    </inertial>
    <visual>
      <origin rpy="0 0 0" xyz="0 0 0"/>
      <geometry>
        <mesh filename="package://env_description/meshes/tray.STL"/>
      </geometry>
      <material name="">
        <color rgba="0.196078431372549 0.666666666666667 1 1"/>
      </material>
    </visual>
    <collision>
      <origin rpy="0 0 0" xyz="0 0 0"/>
      <geometry>
        <mesh filename="package://env_description/meshes/tray.STL"/>
      </geometry>
    </collision>
  </link>
  <joint name="joint_tray" type="fixed">
    <origin rpy="0 0 0" xyz="1.59999999999999 -0.624999999999999 0"/>
    <parent link="env_base_link"/>
    <child link="tray"/>
    <axis xyz="0 0 0"/>
  </joint>
  <link name="AGV">
    <inertial>
      <origin rpy="0 0 0" xyz="0.00135004143913542 0.234508870444381 1.70270626965956"/>
      <mass value="14.935665799643"/>
      <inertia ixx="0.754277136477483" ixy="2.43224651245558E-05" ixz="-8.9812949673114E-05" iyy="1.93577237306899" iyz="-1.20668149742138E-10" izz="1.1817168708026"/>
    </inertial>
    <visual>
      <origin rpy="0 0 0" xyz="0 0 0"/>
      <geometry>
        <mesh filename="package://env_description/meshes/AGV.STL"/>
      </geometry>
      <material name="">
        <color rgba="0.223529411764706 0.223529411764706 0.223529411764706 1"/>
      </material>
    </visual>
    <collision>
      <origin rpy="0 0 0" xyz="0 0 0"/>
      <geometry>
        <mesh filename="package://env_description/meshes/AGV.STL"/>
      </geometry>
    </collision>
  </link>
  <joint name="joint_AGV" type="fixed">
    <origin rpy="3.14159265358979 0 0" xyz="1.43948681363675 1.19509218019732 1.69950000000061"/>
    <parent link="env_base_link"/>
    <child link="AGV"/>
    <axis xyz="0 0 0"/>
  </joint>
  <link name="cabinet">
    <inertial>
      <origin rpy="0 0 0" xyz="1.18348950260654 -0.0420826914896073 -1.11892317501143"/>
      <mass value="266.622014680259"/>
      <inertia ixx="387.69456346984" ixy="-0.000180384929060103" ixz="120.030808565258" iyy="508.581311104087" iyz="-0.000180738000790268" izz="130.258802513168"/>
    </inertial>
    <visual>
      <origin rpy="0 0 0" xyz="0 0 0"/>
      <geometry>
        <mesh filename="package://env_description/meshes/cabinet.STL"/>
      </geometry>
      <material name="">
        <color rgba="0.717647058823529 0.811764705882353 0.764705882352941 1"/>
      </material>
    </visual>
    <collision>
      <origin rpy="0 0 0" xyz="0 0 0"/>
      <geometry>
        <mesh filename="package://env_description/meshes/cabinet.STL"/>
      </geometry>
    </collision>
  </link>
  <joint name="joint_cabinet" type="fixed">
    <origin rpy="0 0 3.14159265358979" xyz="1.96000000000315 1.01500000000955 3.02799956939046"/>
    <parent link="env_base_link"/>
    <child link="cabinet"/>
    <axis xyz="0 0 0"/>
  </joint>
  <link name="ee_base_link">
    <inertial>
      <origin rpy="0 0 0" xyz="-0.0315825451460077 0.0884468369126826 0.0724994852518057"/>
      <mass value="1.97691631503348"/>
      <inertia ixx="0.0177175290942923" ixy="-1.55927242375705E-05" ixz="-1.61455385878767E-06" iyy="0.0185480963265998" iyz="-7.6495979640586E-07" izz="0.0194249721655364"/>
    </inertial>
    <visual>
      <origin rpy="0 0 0" xyz="0 0 0"/>
      <geometry>
        <mesh filename="package://ee_description/meshes/ee_base_link.STL"/>
      </geometry>
      <material name="">
        <color rgba="0.529411764705882 0.549019607843137 0.549019607843137 1"/>
      </material>
    </visual>
    <collision>
      <origin rpy="0 0 0" xyz="0 0 0"/>
      <geometry>
        <mesh filename="package://ee_description/meshes/ee_base_link.STL"/>
      </geometry>
    </collision>
  </link>
  <link name="ee">
    <inertial>
      <origin rpy="0 0 0" xyz="-0.01376744252958 0.0105185069538265 -0.042821327834385"/>
      <mass value="14.8246047798321"/>
      <inertia ixx="0.169687053802028" ixy="-0.00456436315901842" ixz="3.71519809177454E-07" iyy="0.379644529251002" iyz="-1.93054109823794E-07" izz="0.547057358639197"/>
    </inertial>
    <visual>
      <origin rpy="0 0 0" xyz="0 0 0"/>
      <geometry>
        <mesh filename="package://ee_description/meshes/ee.STL"/>
      </geometry>
      <material name="">
        <color rgba="1 1 1 1"/>
      </material>
    </visual>
    <collision>
      <origin rpy="0 0 0" xyz="0 0 0"/>
      <geometry>
        <mesh filename="package://ee_description/meshes/ee.STL"/>
      </geometry>
    </collision>
  </link>
  <joint name="joint_ee" type="fixed">
    <origin rpy="0 0 0" xyz="0 0 0.316"/>
    <parent link="ee_base_link"/>
    <child link="ee"/>
    <axis xyz="0 0 0"/>
  </joint>
  <link name="world"/>
  <joint name="world_to_env" type="fixed">
    <parent link="world"/>
    <child link="env_base_link"/>
    <origin rpy="-1.5707963268 0 3.1415926535" xyz="0 0 1.2"/>
  </joint>
  <joint name="env_to_kuka_joint" type="fixed">
    <parent link="env_base_link"/>
    <child link="base_link"/>
    <!-- <origin xyz="0 0 0" rpy="1.5707963268 1.5707963268 0.78539816338" /> -->
    <origin rpy="1.5707963268 2.3561944901 0" xyz="0 0 0"/>
  </joint>
  <joint name="kuka_to_ee_joint" type="fixed">
    <parent link="link_6"/>
    <child link="ee_base_link"/>
    <origin rpy="0 0 0" xyz="0 0 0"/>
  </joint>
</robot>
